<mujoco model="Adroit">
  <asset>
    <material name="MatColl" reflectance="0.5" rgba="0.4 0.5 0.6 1" shininess="0.3" specular="1"/>
    <material name="MatViz" reflectance="0.5" rgba="0.9 0.7 0.5 1" shininess="0.1" specular="0.75"/>
    <mesh
        file="/home/sim/project/xiaolong_hand/hand_imitation/hand_imitation/env/models/assets/adroit/meshes/forearm_simple.stl"
        name="forearm_simple" scale="1 1 1"/>
    <mesh file="/home/sim/project/xiaolong_hand/hand_imitation/hand_imitation/env/models/assets/adroit/meshes/wrist.stl"
          name="wrist" scale="0.001 0.001 0.001"/>
    <mesh file="/home/sim/project/xiaolong_hand/hand_imitation/hand_imitation/env/models/assets/adroit/meshes/palm.stl"
          name="palm" scale="0.001 0.001 0.001"/>
    <mesh
        file="/home/sim/project/xiaolong_hand/hand_imitation/hand_imitation/env/models/assets/adroit/meshes/lfmetacarpal.stl"
        name="lfmetacarpal" scale="0.001 0.001 0.001"/>
    <mesh
        file="/home/sim/project/xiaolong_hand/hand_imitation/hand_imitation/env/models/assets/adroit/meshes/knuckle.stl"
        name="knuckle" scale="0.001 0.001 0.001"/>
    <mesh file="/home/sim/project/xiaolong_hand/hand_imitation/hand_imitation/env/models/assets/adroit/meshes/F3.stl"
          name="F3" scale="0.001 0.001 0.001"/>
    <mesh file="/home/sim/project/xiaolong_hand/hand_imitation/hand_imitation/env/models/assets/adroit/meshes/F2.stl"
          name="F2" scale="0.001 0.001 0.001"/>
    <mesh file="/home/sim/project/xiaolong_hand/hand_imitation/hand_imitation/env/models/assets/adroit/meshes/F1.stl"
          name="F1" scale="0.001 0.001 0.001"/>
    <mesh file="/home/sim/project/xiaolong_hand/hand_imitation/hand_imitation/env/models/assets/adroit/meshes/TH3_z.stl"
          name="TH3_z" scale="0.001 0.001 0.001"/>
    <mesh file="/home/sim/project/xiaolong_hand/hand_imitation/hand_imitation/env/models/assets/adroit/meshes/TH2_z.stl"
          name="TH2_z" scale="0.001 0.001 0.001"/>
    <mesh file="/home/sim/project/xiaolong_hand/hand_imitation/hand_imitation/env/models/assets/adroit/meshes/TH1_z.stl"
          name="TH1_z" scale="0.001 0.001 0.001"/>
    <texture builtin="gradient" height="256" rgb1=".9 .9 1." rgb2=".2 .3 .4" type="skybox" width="256"/>
    <texture
        file="/home/sim/project/xiaolong_hand/hand_imitation/hand_imitation/env/models/assets/arenas/../textures/wood-tiles.png"
        name="texplane" type="2d"/>
    <material name="floorplane" reflectance="0.01" shininess="0.0" specular="0.0" texrepeat="2 2" texture="texplane"
              texuniform="true"/>

    <texture
        file="/home/sim/project/xiaolong_hand/hand_imitation/hand_imitation/env/models/assets/arenas/../textures/ceramic.png"
        name="tex-ceramic" type="cube"/>
    <material name="table_ceramic" reflectance="0.0" shininess="0.0" specular="0.2" texrepeat="1 1"
              texture="tex-ceramic"/>

    <texture
        file="/home/sim/project/xiaolong_hand/hand_imitation/hand_imitation/env/models/assets/arenas/../textures/steel-brushed.png"
        name="tex-steel-brushed" type="cube"/>
    <material name="table_legs_metal" reflectance="0.8" shininess="0.8" texrepeat="1 1" texture="tex-steel-brushed"/>

    <texture
        file="/home/sim/project/xiaolong_hand/hand_imitation/hand_imitation/env/models/assets/arenas/../textures/cream-plaster.png"
        name="tex-cream-plaster" type="2d"/>
    <material name="walls_mat" reflectance="0.0" shininess="0.1" specular="0.1" texrepeat="3 3"
              texture="tex-cream-plaster" texuniform="true"/>

    <texture builtin="flat" height="512" name="textable" rgb1="0.5 0.5 0.5" rgb2="0.5 0.5 0.5" width="512"/>
    <material name="table_mat" texture="textable"/>
  </asset>
  <worldbody>
    <body name="forearm" pos="0 -0.7 0.2" quat="0.000563312 -0.000562864 0.706825 0.707388">
      <inertial diaginertia="0.01 0.01 0.0075" mass="4" pos="0.001 -0.002 0.29" quat="0.982037 -0.0160006 0 -0.188007"/>
<!--      <joint armature="0.001" axis="1 0 0" damping="20" frictionloss="0.001" limited="true" margin="0.01" name="ARTx"-->
<!--             pos="0 0 0" range="-0.25 0.25" type="slide"/>-->
<!--      <joint armature="0.001" axis="0 1 0" damping="20" frictionloss="0.001" limited="true" margin="0.01" name="ARTy"-->
<!--             pos="0 0 0" range="0 0.2" type="slide"/>-->
<!--      <joint armature="0.001" axis="0 0 1" damping="20" frictionloss="0.001" limited="true" margin="0.01" name="ARTz"-->
<!--             pos="0 0 0" range="-0.3 0.5" type="slide"/>-->
<!--      <joint armature="0.001" axis="1 0 0" damping="20" frictionloss="0.001" limited="true" margin="0.01" name="ARRx"-->
<!--             pos="0 0 0" range="-0.75 0.75"/>-->
<!--      <joint armature="0.001" axis="0 1 0" damping="20" frictionloss="0.001" limited="true" margin="0.01" name="ARRy"-->
<!--             pos="0 0 0" range="-0.75 0.75"/>-->
<!--      <joint armature="0.001" axis="0 0 1" damping="20" frictionloss="0.001" limited="true" margin="0.01" name="ARRz"-->
<!--             pos="0 0 0" range="-0.75 0.75"/>-->
      <geom conaffinity="0" contype="0" friction="1 0.5 0.01" group="1" margin="0.0005" material="MatViz"
            mesh="forearm_simple" name="V_forearm" pos="0 -0.01 0.181" quat="0.707388 0 0 -0.706825" type="mesh"/>
      <geom conaffinity="0" friction="1 0.5 0.01" group="4" margin="0.0005" material="MatColl" name="C_forearm1"
            pos="0 0 0.29" rgba="0.4 0.5 0.6 0.1" size="0.05 0.033" type="capsule"/>
      <body name="wrist" pos="0 0 0.396">
        <inertial diaginertia="0.001 0.001 0.001" mass="0.3" pos="0.003 0 0.016"
                  quat="0.504234 0.49623 0.49523 0.504234"/>
        <joint armature="0.005" axis="0 1 0" damping="0.5" frictionloss="0.001" limited="true" margin="0.01" name="WRJ1" type="hinge"
               pos="0 0 0" range="-0.524 0.175" user="1123"/>
        <geom conaffinity="0" contype="0" friction="1 0.5 0.01" group="1" margin="0.0005" material="MatViz" mesh="wrist"
              name="V_wrist" type="mesh"/>
        <geom conaffinity="0" friction="1 0.5 0.01" group="4" margin="0.0005" material="MatColl" name="C_wrist"
              quat="0.707107 0.707107 0 0" rgba="0.4 0.5 0.6 0.1" size="0.015 0.01" type="capsule"/>
        <body name="palm" pos="0 0 0.034">
          <inertial diaginertia="0.001 0.001 0.001" mass="0.3" pos="0.006 0 0.036"
                    quat="0.715833 0.0439898 0.0749825 0.692839"/>
          <joint armature="0.001" axis="1 0 0" damping="0.05" frictionloss="0.001" limited="true" margin="0.01" type="hinge"
                 name="WRJ0" pos="0 0 0" range="-0.785 0.611" user="1122"/>
          <geom conaffinity="0" contype="0" friction="1 0.5 0.01" group="1" margin="0.0005" material="MatViz"
                mesh="palm" name="V_palm" type="mesh"/>
          <geom conaffinity="0" friction="1 0.5 0.01" group="4" margin="0.0005" material="MatColl" name="C_palm0"
                pos="0.011 0 0.038" rgba="0.4 0.5 0.6 0.1" size="0.032 0.0111 0.049" type="box"/>
          <geom conaffinity="0" friction="1 0.5 0.01" group="4" margin="0.0005" material="MatColl" name="C_palm1"
                pos="-0.032 0 0.014" rgba="0.4 0.5 0.6 0.1" size="0.011 0.0111 0.025" type="box"/>
          <site name="S_grasp" pos="0.007 -0.05 0.07" quat="0.00863043 -0.595202 -0.00337281 -0.803523" rgba="0 0 0 0"
                size="0.01"/>
          <site group="4" name="Tch_ffmetacarpal" pos="0.033 -0.008 0.078" rgba="0.8 0.8 0.8 0.15"
                size="0.009 0.004 0.006" type="box"/>
          <site group="4" name="Tch_mfmetacarpal" pos="0.011 -0.008 0.074" rgba="0.8 0.8 0.8 0.15"
                size="0.009 0.004 0.014" type="box"/>
          <site group="4" name="Tch_rfmetacarpal" pos="-0.011 -0.008 0.068" rgba="0.8 0.8 0.8 0.15"
                size="0.009 0.004 0.016" type="box"/>
          <site group="4" name="Tch_thmetacarpal" pos="0.006 -0.008 0.042" quat="0.959662 0 0.281157 0"
                rgba="0.8 0.8 0.8 0.15" size="0.008 0.004 0.015" type="box"/>
          <site group="4" name="Tch_palm" pos="-0.017 -0.008 0.024" quat="0.877583 0 -0.479426 0"
                rgba="0.8 0.8 0.8 0.15" size="0.012 0.004 0.016" type="box"/>
          <body name="ffknuckle" pos="0.033 0 0.095">
            <inertial diaginertia="1e-05 1e-05 1e-05" mass="0.008" pos="0 0 0"
                      quat="0.520062 0.854102 0.00600072 -0.00300036"/>
            <joint armature="0.001" axis="0 1 0" damping="0.05" frictionloss="0.001" limited="true" margin="0.01" type="hinge"
                   name="FFJ3" pos="0 0 0" range="-0.436 0.436" user="1103"/>
            <geom conaffinity="0" contype="0" friction="1 0.5 0.01" group="1" margin="0.0005" material="MatViz"
                  mesh="knuckle" name="V_ffknuckle" type="mesh"/>
            <body name="ffproximal" pos="0 0 0">
              <inertial diaginertia="1e-05 1e-05 1e-05" mass="0.014" pos="0 0 0.023"
                        quat="0.707095 -0.00400054 0.00400054 0.707095"/>
              <joint armature="0.001" axis="1 0 0" damping="0.05" frictionloss="0.001" limited="true" margin="0.01" type="hinge"
                     name="FFJ2" pos="0 0 0" range="0 1.571" user="1102"/>
              <geom conaffinity="0" contype="0" friction="1 0.5 0.01" group="1" margin="0.0005" material="MatViz"
                    mesh="F3" name="V_ffproximal" type="mesh"/>
              <geom conaffinity="0" friction="1 0.5 0.01" group="4" margin="0.0005" material="MatColl"
                    name="C_ffproximal" pos="0 0 0.0225" size="0.01 0.0225" type="capsule"/>
              <site group="4" name="Tch_ffproximal" pos="0 -0.007 0.022" rgba="0.8 0.8 0.8 0.15"
                    size="0.009 0.004 0.012" type="box"/>
              <body name="ffmiddle" pos="0 0 0.045">
                <inertial diaginertia="1e-05 1e-05 1e-05" mass="0.012" pos="0 0 0.011" quat="0.707107 0 0 0.707107"/>
                <joint armature="0.001" axis="1 0 0" damping="0.05" frictionloss="0.001" limited="true" margin="0.01" type="hinge"
                       name="FFJ1" pos="0 0 0" range="0 1.571" user="1101"/>
                <geom conaffinity="0" contype="0" friction="1 0.5 0.01" group="1" margin="0.0005" material="MatViz"
                      mesh="F2" name="V_ffmiddle" type="mesh"/>
                <geom conaffinity="0" friction="1 0.5 0.01" group="4" margin="0.0005" material="MatColl"
                      name="C_ffmiddle" pos="0 0 0.0125" size="0.00805 0.0125" type="capsule"/>
                <site group="4" name="Tch_ffmiddle" pos="0 -0.007 0.013" rgba="0.8 0.8 0.8 0.15"
                      size="0.009 0.002 0.007" type="box"/>
                <body name="ffdistal" pos="0 0 0.025">
                  <inertial diaginertia="1e-05 1e-05 1e-05" mass="0.01" pos="0 0 0.015"
                            quat="0.7071 -0.00300043 0.00300043 0.7071"/>
                  <joint armature="0.001" axis="1 0 0" damping="0.05" frictionloss="0.001" limited="true" margin="0.01" type="hinge"
                         name="FFJ0" pos="0 0 0" range="0 1.571" user="1100"/>
                  <geom conaffinity="0" contype="0" friction="1 0.5 0.01" group="1" margin="0.0005" material="MatViz"
                        mesh="F1" name="V_ffdistal" pos="0 0 0.001" type="mesh"/>
                  <geom conaffinity="0" condim="4" friction="1 0.5 0.01" group="4" margin="0.0005" material="MatColl"
                        name="C_ffdistal" pos="0 0 0.012" size="0.00705 0.012" type="capsule"/>
                  <site group="3" name="S_fftip" pos="0 0 0.026" rgba="0.4 0.9 0.4 1" size="0.005 0 0"/>
                  <site group="4" name="Tch_fftip" pos="0 -0.004 0.018" rgba="0.8 0.8 0.8 0.15" size="0.009 0.004 0.013"
                        type="box"/>
                </body>
              </body>
            </body>
          </body>
          <body name="mfknuckle" pos="0.011 0 0.099">
            <inertial diaginertia="1e-05 1e-05 1e-05" mass="0.008" pos="0 0 0"
                      quat="0.520062 0.854102 0.00600072 -0.00300036"/>
            <joint armature="0.001" axis="0 1 0" damping="0.05" frictionloss="0.001" limited="true" margin="0.01" type="hinge"
                   name="MFJ3" pos="0 0 0" range="-0.436 0.436" user="1107"/>
            <geom conaffinity="0" contype="0" friction="1 0.5 0.01" group="1" margin="0.0005" material="MatViz"
                  mesh="knuckle" name="V_mfknuckle" type="mesh"/>
            <body name="mfproximal" pos="0 0 0">
              <inertial diaginertia="1e-05 1e-05 1e-05" mass="0.014" pos="0 0 0.023"
                        quat="0.707095 -0.00400054 0.00400054 0.707095"/>
              <joint armature="0.001" axis="1 0 0" damping="0.05" frictionloss="0.001" limited="true" margin="0.01" type="hinge"
                     name="MFJ2" pos="0 0 0" range="0 1.571" user="1106"/>
              <geom conaffinity="0" contype="0" friction="1 0.5 0.01" group="1" margin="0.0005" material="MatViz"
                    mesh="F3" name="V_mfproximal" type="mesh"/>
              <geom conaffinity="0" friction="1 0.5 0.01" group="4" margin="0.0005" material="MatColl"
                    name="C_mfproximal" pos="0 0 0.0225" size="0.01 0.0225" type="capsule"/>
              <site group="4" name="Tch_mfproximal" pos="0 -0.007 0.022" rgba="0.8 0.8 0.8 0.15"
                    size="0.009 0.004 0.012" type="box"/>
              <body name="mfmiddle" pos="0 0 0.045">
                <inertial diaginertia="1e-05 1e-05 1e-05" mass="0.012" pos="0 0 0.012" quat="0.707107 0 0 0.707107"/>
                <joint armature="0.001" axis="1 0 0" damping="0.05" frictionloss="0.001" limited="true" margin="0.01" type="hinge"
                       name="MFJ1" pos="0 0 0" range="0 1.571" user="1105"/>
                <geom conaffinity="0" contype="0" friction="1 0.5 0.01" group="1" margin="0.0005" material="MatViz"
                      mesh="F2" name="V_mfmiddle" type="mesh"/>
                <geom conaffinity="0" friction="1 0.5 0.01" group="4" margin="0.0005" material="MatColl"
                      name="C_mfmiddle" pos="0 0 0.0125" size="0.00805 0.0125" type="capsule"/>
                <site group="4" name="Tch_mfmiddle" pos="0 -0.007 0.013" rgba="0.8 0.8 0.8 0.15"
                      size="0.009 0.002 0.007" type="box"/>
                <body name="mfdistal" pos="0 0 0.025">
                  <inertial diaginertia="1e-05 1e-05 1e-05" mass="0.01" pos="0 0 0.015"
                            quat="0.7071 -0.00300043 0.00300043 0.7071"/>
                  <joint armature="0.001" axis="1 0 0" damping="0.05" frictionloss="0.001" limited="true" margin="0.01" type="hinge"
                         name="MFJ0" pos="0 0 0" range="0 1.571" user="1104"/>
                  <geom conaffinity="0" contype="0" friction="1 0.5 0.01" group="1" margin="0.0005" material="MatViz"
                        mesh="F1" name="V_mfdistal" type="mesh"/>
                  <geom conaffinity="0" condim="4" friction="1 0.5 0.01" group="4" margin="0.0005" material="MatColl"
                        name="C_mfdistal" pos="0 0 0.012" size="0.00705 0.012" type="capsule"/>
                  <site group="3" name="S_mftip" pos="0 0 0.026" rgba="0.4 0.9 0.4 1" size="0.005 0 0"/>
                  <site group="4" name="Tch_mftip" pos="0 -0.004 0.018" rgba="0.8 0.8 0.8 0.15" size="0.009 0.004 0.013"
                        type="box"/>
                </body>
              </body>
            </body>
          </body>
          <body name="rfknuckle" pos="-0.011 0 0.095">
            <inertial diaginertia="1e-05 1e-05 1e-05" mass="0.008" pos="0 0 0"
                      quat="0.520062 0.854102 0.00600072 -0.00300036"/>
            <joint armature="0.001" axis="0 1 0" damping="0.05" frictionloss="0.001" limited="true" margin="0.01" type="hinge"
                   name="RFJ3" pos="0 0 0" range="-0.436 0.436" user="1111"/>
            <geom conaffinity="0" contype="0" friction="1 0.5 0.01" group="1" margin="0.0005" material="MatViz"
                  mesh="knuckle" name="V_rfknuckle" type="mesh"/>
            <body name="rfproximal" pos="0 0 0">
              <inertial diaginertia="1e-05 1e-05 1e-05" mass="0.014" pos="0 0 0.023"
                        quat="0.707095 -0.00400054 0.00400054 0.707095"/>
              <joint armature="0.001" axis="1 0 0" damping="0.05" frictionloss="0.001" limited="true" margin="0.01" type="hinge"
                     name="RFJ2" pos="0 0 0" range="0 1.571" user="1110"/>
              <geom conaffinity="0" contype="0" friction="1 0.5 0.01" group="1" margin="0.0005" material="MatViz"
                    mesh="F3" name="V_rfproximal" type="mesh"/>
              <geom conaffinity="0" friction="1 0.5 0.01" group="4" margin="0.0005" material="MatColl"
                    name="C_rfproximal" pos="0 0 0.0225" size="0.01 0.0225" type="capsule"/>
              <site group="4" name="Tch_rfproximal" pos="0 -0.007 0.022" rgba="0.8 0.8 0.8 0.15"
                    size="0.009 0.004 0.012" type="box"/>
              <body name="rfmiddle" pos="0 0 0.045">
                <inertial diaginertia="1e-05 1e-05 1e-05" mass="0.012" pos="0 0 0.012" quat="0.707107 0 0 0.707107"/>
                <joint armature="0.001" axis="1 0 0" damping="0.05" frictionloss="0.001" limited="true" margin="0.01" type="hinge"
                       name="RFJ1" pos="0 0 0" range="0 1.571" user="1109"/>
                <geom conaffinity="0" contype="0" friction="1 0.5 0.01" group="1" margin="0.0005" material="MatViz"
                      mesh="F2" name="V_rfmiddle" type="mesh"/>
                <geom conaffinity="0" friction="1 0.5 0.01" group="4" margin="0.0005" material="MatColl"
                      name="C_rfmiddle" pos="0 0 0.0125" size="0.00805 0.0125" type="capsule"/>
                <site group="4" name="Tch_rfmiddle" pos="0 -0.007 0.013" rgba="0.8 0.8 0.8 0.15"
                      size="0.009 0.002 0.007" type="box"/>
                <body name="rfdistal" pos="0 0 0.025">
                  <inertial diaginertia="1e-05 1e-05 1e-05" mass="0.01" pos="0 0 0.015"
                            quat="0.7071 -0.00300043 0.00300043 0.7071"/>
                  <joint armature="0.001" axis="1 0 0" damping="0.05" frictionloss="0.001" limited="true" margin="0.01" type="hinge"
                         name="RFJ0" pos="0 0 0" range="0 1.571" user="1108"/>
                  <geom conaffinity="0" contype="0" friction="1 0.5 0.01" group="1" margin="0.0005" material="MatViz"
                        mesh="F1" name="V_rfdistal" pos="0 0 0.001" type="mesh"/>
                  <geom conaffinity="0" condim="4" friction="1 0.5 0.01" group="4" margin="0.0005" material="MatColl"
                        name="C_rfdistal" pos="0 0 0.012" size="0.00705 0.012" type="capsule"/>
                  <site group="3" name="S_rftip" pos="0 0 0.026" rgba="0.4 0.9 0.4 1" size="0.005 0 0"/>
                  <site group="4" name="Tch_rftip" pos="0 -0.004 0.018" rgba="0.8 0.8 0.8 0.15" size="0.009 0.004 0.013"
                        type="box"/>
                </body>
              </body>
            </body>
          </body>
          <body name="lfmetacarpal" pos="-0.017 0 0.044">
            <inertial diaginertia="1e-05 1e-05 1e-05" mass="0.075" pos="-0.014 0.001 0.014"
                      quat="0.709167 -0.0920216 -0.0630148 0.696164"/>
            <joint armature="0.001" axis="0.570977 0 0.820966" damping="0.05" frictionloss="0.001" limited="true" type="hinge"
                   margin="0.01" name="LFJ4" pos="0 0 0" range="0 0.698" user="1116"/>
            <geom conaffinity="0" contype="0" friction="1 0.5 0.01" group="1" margin="0.0005" material="MatViz"
                  mesh="lfmetacarpal" name="V_lfmetacarpal" pos="-0.016 0 -0.023" type="mesh"/>
            <geom conaffinity="0" friction="1 0.5 0.01" group="4" margin="0.0005" material="MatColl"
                  name="C_lfmetacarpal" pos="-0.0165 0 0.01" rgba="0.4 0.5 0.6 0.2" size="0.0095 0.0111 0.025"
                  type="box"/>
            <site group="4" name="Tch_lfmetacarpal" pos="-0.016 -0.008 0.017" rgba="0.8 0.8 0.8 0.15"
                  size="0.009 0.004 0.014" type="box"/>
            <body name="lfknuckle" pos="-0.017 0 0.044">
              <inertial diaginertia="1e-05 1e-05 1e-05" mass="0.008" pos="0 0 0"
                        quat="0.520062 0.854102 0.00600072 -0.00300036"/>
              <joint armature="0.001" axis="0 1 0" damping="0.05" frictionloss="0.001" limited="true" margin="0.01" type="hinge"
                     name="LFJ3" pos="0 0 0" range="-0.436 0.436" user="1115"/>
              <geom conaffinity="0" contype="0" friction="1 0.5 0.01" group="1" margin="0.0005" material="MatViz"
                    mesh="knuckle" name="V_lfknuckle" type="mesh"/>
              <body name="lfproximal" pos="0 0 0">
                <inertial diaginertia="1e-05 1e-05 1e-05" mass="0.014" pos="0 0 0.023"
                          quat="0.707095 -0.00400054 0.00400054 0.707095"/>
                <joint armature="0.001" axis="1 0 0" damping="0.05" frictionloss="0.001" limited="true" margin="0.01" type="hinge"
                       name="LFJ2" pos="0 0 0" range="0 1.571" user="1114"/>
                <geom conaffinity="0" contype="0" friction="1 0.5 0.01" group="1" margin="0.0005" material="MatViz"
                      mesh="F3" name="V_lfproximal" type="mesh"/>
                <geom conaffinity="0" friction="1 0.5 0.01" group="4" margin="0.0005" material="MatColl"
                      name="C_lfproximal" pos="0 0 0.0225" size="0.01 0.0225" type="capsule"/>
                <site group="4" name="Tch_lfproximal" pos="0 -0.007 0.022" rgba="0.8 0.8 0.8 0.15"
                      size="0.009 0.004 0.012" type="box"/>
                <body name="lfmiddle" pos="0 0 0.045">
                  <inertial diaginertia="1e-05 1e-05 1e-05" mass="0.012" pos="0 0 0.012" quat="0.707107 0 0 0.707107"/>
                  <joint armature="0.001" axis="1 0 0" damping="0.05" frictionloss="0.001" limited="true" margin="0.01" type="hinge"
                         name="LFJ1" pos="0 0 0" range="0 1.571" user="1113"/>
                  <geom conaffinity="0" contype="0" friction="1 0.5 0.01" group="1" margin="0.0005" material="MatViz"
                        mesh="F2" name="V_lfmiddle" type="mesh"/>
                  <geom conaffinity="0" friction="1 0.5 0.01" group="4" margin="0.0005" material="MatColl"
                        name="C_lfmiddle" pos="0 0 0.0125" size="0.00805 0.0125" type="capsule"/>
                  <site group="4" name="Tch_lfmiddle" pos="0 -0.007 0.013" rgba="0.8 0.8 0.8 0.15"
                        size="0.009 0.002 0.007" type="box"/>
                  <body name="lfdistal" pos="0 0 0.025">
                    <inertial diaginertia="1e-05 1e-05 1e-05" mass="0.01" pos="0 0 0.015"
                              quat="0.7071 -0.00300043 0.00300043 0.7071"/>
                    <joint armature="0.001" axis="1 0 0" damping="0.05" frictionloss="0.001" limited="true" type="hinge"
                           margin="0.01" name="LFJ0" pos="0 0 0" range="0 1.571" user="1112"/>
                    <geom conaffinity="0" contype="0" friction="1 0.5 0.01" group="1" margin="0.0005" material="MatViz"
                          mesh="F1" name="V_lfdistal" pos="0 0 0.001" type="mesh"/>
                    <geom conaffinity="0" condim="4" friction="1 0.5 0.01" group="4" margin="0.0005" material="MatColl"
                          name="C_lfdistal" pos="0 0 0.012" size="0.00705 0.012" type="capsule"/>
                    <site group="3" name="S_lftip" pos="0 0 0.026" rgba="0.4 0.9 0.4 1" size="0.005 0 0"/>
                    <site group="4" name="Tch_lftip" pos="0 -0.004 0.018" rgba="0.8 0.8 0.8 0.15"
                          size="0.009 0.004 0.013" type="box"/>
                  </body>
                </body>
              </body>
            </body>
          </body>
          <body name="thbase" pos="0.034 -0.009 0.029" quat="0.923956 0 0.382499 0">
            <inertial diaginertia="1e-05 1e-05 1e-05" mass="0.01" pos="0 0 0"/>
            <joint armature="0.001" axis="0 0 -1" damping="0.05" frictionloss="0.001" limited="true" margin="0.01" type="hinge"
                   name="THJ4" pos="0 0 0" range="-1.047 1.047" user="1121"/>
            <geom group="1" name="V_thbase" size="0.001 0.001 0.001" type="box"/>
            <body name="thproximal" pos="0 0 0">
              <inertial diaginertia="1e-05 1e-05 1e-05" mass="0.016" pos="0 0 0.017"
                        quat="0.981604 0 0.000999597 0.190923"/>
              <joint armature="0.001" axis="1 0 0" damping="0.05" frictionloss="0.001" limited="true" margin="0.01" type="hinge"
                     name="THJ3" pos="0 0 0" range="0 1.309" user="1120"/>
              <geom conaffinity="0" contype="0" friction="1 0.5 0.01" group="1" margin="0.0005" material="MatViz"
                    mesh="TH3_z" name="V_thproximal" type="mesh"/>
              <geom conaffinity="0" friction="1 0.5 0.01" group="4" margin="0.0005" material="MatColl"
                    name="C_thproximal" pos="0 0 0.019" rgba="0.4 0.5 0.6 0.1" size="0.013 0.019" type="capsule"/>
              <site group="4" name="Tch_thproximal" pos="-0.008 0 0.022" rgba="0.8 0.8 0.8 0.15"
                    size="0.005 0.011 0.011" type="box"/>
              <body name="thhub" pos="0 0 0.038">
                <inertial diaginertia="1e-05 1e-05 1e-05" mass="0.002" pos="0 0 0"/>
                <joint armature="0.001" axis="1 0 0" damping="0.05" frictionloss="0.001" limited="true" margin="0.01" type="hinge"
                       name="THJ2" pos="0 0 0" range="-0.262 0.262" user="1119"/>
                <geom group="1" name="V_thhub" size="0.001 0.001 0.001" type="box"/>
                <body name="thmiddle" pos="0 0 0">
                  <inertial diaginertia="1e-05 1e-05 1e-05" mass="0.016" pos="0 0 0.016"
                            quat="0.999971 -0.000999971 -0.00699979 0.00299991"/>
                  <joint armature="0.001" axis="0 1 0" damping="0.05" frictionloss="0.001" limited="true" margin="0.01" type="hinge"
                         name="THJ1" pos="0 0 0" range="-0.524 0.524" user="1118"/>
                  <geom conaffinity="0" contype="0" friction="1 0.5 0.01" group="1" margin="0.0005" material="MatViz"
                        mesh="TH2_z" name="V_thmiddle" type="mesh"/>
                  <geom conaffinity="0" friction="1 0.5 0.01" group="4" margin="0.0005" material="MatColl"
                        name="C_thmiddle" pos="0 0 0.016" size="0.011 0.016" type="capsule"/>
                  <site group="4" name="Tch_thmiddle" pos="-0.008 0 0.018" rgba="0.8 0.8 0.8 0.15"
                        size="0.005 0.011 0.011" type="box"/>
                  <body name="thdistal" pos="0 0 0.032">
                    <inertial diaginertia="1e-05 1e-05 1e-05" mass="0.016" pos="0 0 0.016"
                              quat="0.99887 -0.00499935 -0.0469939 0.00499935"/>
                    <joint armature="0.001" axis="0 1 0" damping="0.05" frictionloss="0.001" limited="true" type="hinge"
                           margin="0.01" name="THJ0" pos="0 0 0" range="-1.571 0" user="1117"/>
                    <geom conaffinity="0" contype="0" friction="1 0.5 0.01" group="1" margin="0.0005" material="MatViz"
                          mesh="TH1_z" name="V_thdistal" type="mesh"/>
                    <geom conaffinity="0" condim="4" friction="1 0.5 0.01" group="4" margin="0.0005" material="MatColl"
                          name="C_thdistal" pos="0 0 0.013" size="0.00918 0.013" type="capsule"/>
                    <site group="3" name="S_thtip" pos="0 0 0.0275" rgba="0.4 0.9 0.4 1" size="0.005 0 0"/>
                    <site group="4" name="Tch_thtip" pos="-0.005 0 0.02" rgba="0.8 0.8 0.8 0.15"
                          size="0.005 0.011 0.016" type="box"/>
                  </body>
                </body>
              </body>
            </body>
          </body>
        </body>
      </body>
    </body>
  </worldbody>
</mujoco>